<mujoco model="gello_arm">
    <compiler angle="degree" />
    <option timestep="0.01" />

    <worldbody>
        <body name="base" pos="0 0 0">
            <geom type="box" size="0.05 0.05 0.02" rgba="0.8 0.2 0.2 1" />

            <body name="link1" pos="0 0 0.02">
                <joint name="q1" type="hinge" axis="0 0 1" range="-235 35" />
                <geom type="capsule" size="0.01 0.02" fromto="0 0 0 0 0 0.02" rgba="0.2 0.6 0.8 1" />

                <body name="link2" pos="0 0 0.02">
                    <joint name="q2" type="hinge" axis="1 0 0" range="0 135" />
                    <geom type="capsule" size="0.01 0.2" fromto="0 0 0 0 0.2 0" rgba="0.8 0.8 0.2 1" />

                    <body name="link3" pos="0 0.2 0">
                        <joint name="q3" type="hinge" axis="1 0 0" range="-135 0" />
                        <geom type="capsule" size="0.01 0.2" fromto="0 0 0 0 0.2 0" rgba="0.2 0.8 0.4 1" />

                        <body name="link4" pos="0 0.2 0">
                            <joint name="q4" type="hinge" axis="1 0 0" range="-202.5 22.5" />
                            <geom type="capsule" size="0.01 0.065" fromto="0 0 0 0 0 0.065" rgba="0.8 0.4 0.6 1" />

                            <body name="link5" pos="0 0 0.065">
                                <joint name="q5" type="hinge" axis="0 0 1" range="-90 90" />
                                <geom type="capsule" size="0.01 0.05" fromto="0 0 0 0 0 0.05" rgba="0.4 0.4 0.8 1" />

                                <body name="link6" pos="0 0 0.05">
                                    <joint name="q6" type="hinge" axis="0 1 0" range="-202.5 22.5" />
                                    <geom type="capsule" size="0.01 0.05" fromto="0 0.05 0 0 0 0" rgba="0.3 0.3 0.3 1" />

                                    <body name="link7" pos="0 0.05 0">
                                        <geom type="capsule" size="0.01 0.05" fromto="0 0 0 0 0 0.05" rgba="0.3 0.3 0.3 1" />
                                    </body>

                                </body>
                            </body>
                        </body>
                    </body>
                </body>
            </body>
        </body>
    </worldbody>

    <actuator>
        <motor joint="q1" ctrlrange="-1 1" />
        <motor joint="q2" ctrlrange="-1 1" />
        <motor joint="q3" ctrlrange="-1 1" />
        <motor joint="q4" ctrlrange="-1 1" />
        <motor joint="q5" ctrlrange="-1 1" />
    </actuator>
</mujoco>
